I'm sorry, but an uncaught exception occurred.

While running game code:
  File "game/script.rpy", line 1185, in script
    $ inventory.antarPaket(paket2)
  File "game/script.rpy", line 1185, in <module>
    $ inventory.antarPaket(paket2)
  File "game/script.rpy", line 233, in antarPaket
    self.item_paket.remove(item)
ValueError: list.remove(x): x not in list

-- Full Traceback ------------------------------------------------------------

Full traceback:
  File "game/script.rpy", line 1185, in script
    $ inventory.antarPaket(paket2)
  File "C:\Users\RidhoJagis\Downloads\Program\renpy-8.0.3-sdk\renpy\ast.py", line 1131, in execute
    renpy.python.py_exec_bytecode(self.code.bytecode, self.hide, store=self.store)
  File "C:\Users\RidhoJagis\Downloads\Program\renpy-8.0.3-sdk\renpy\python.py", line 1061, in py_exec_bytecode
    exec(bytecode, globals, locals)
  File "game/script.rpy", line 1185, in <module>
    $ inventory.antarPaket(paket2)
  File "game/script.rpy", line 233, in antarPaket
    self.item_paket.remove(item)
  File "C:\Users\RidhoJagis\Downloads\Program\renpy-8.0.3-sdk\renpy\revertable.py", line 97, in do_mutation
    return method(self, *args, **kwargs)
ValueError: list.remove(x): x not in list

Windows-10-10.0.22621 AMD64
Ren'Py 8.0.3.22090809
Simulasi_Kurir 1.0
Wed Jun 14 22:32:10 2023
